[2022-02-08 17:37:05,074] {taskinstance.py:1032} INFO - Dependencies all met for <TaskInstance: gcs_to_bq_dag.gcs_2_gcs_task scheduled__2022-02-07T00:00:00+00:00 [queued]>
[2022-02-08 17:37:05,090] {taskinstance.py:1032} INFO - Dependencies all met for <TaskInstance: gcs_to_bq_dag.gcs_2_gcs_task scheduled__2022-02-07T00:00:00+00:00 [queued]>
[2022-02-08 17:37:05,091] {taskinstance.py:1238} INFO - 
--------------------------------------------------------------------------------
[2022-02-08 17:37:05,092] {taskinstance.py:1239} INFO - Starting attempt 20 of 21
[2022-02-08 17:37:05,093] {taskinstance.py:1240} INFO - 
--------------------------------------------------------------------------------
[2022-02-08 17:37:05,105] {taskinstance.py:1259} INFO - Executing <Task(GCSToGCSOperator): gcs_2_gcs_task> on 2022-02-07 00:00:00+00:00
[2022-02-08 17:37:05,111] {standard_task_runner.py:52} INFO - Started process 739 to run task
[2022-02-08 17:37:05,116] {standard_task_runner.py:76} INFO - Running: ['***', 'tasks', 'run', 'gcs_to_bq_dag', 'gcs_2_gcs_task', 'scheduled__2022-02-07T00:00:00+00:00', '--job-id', '729', '--raw', '--subdir', 'DAGS_FOLDER/gcs_2_bq_dag.py', '--cfg-path', '/tmp/tmp9op3vwxx', '--error-file', '/tmp/tmpxj1zg7bb']
[2022-02-08 17:37:05,117] {standard_task_runner.py:77} INFO - Job 729: Subtask gcs_2_gcs_task
[2022-02-08 17:37:05,182] {logging_mixin.py:109} INFO - Running <TaskInstance: gcs_to_bq_dag.gcs_2_gcs_task scheduled__2022-02-07T00:00:00+00:00 [running]> on host c7740c824b7c
[2022-02-08 17:37:05,237] {taskinstance.py:1426} INFO - Exporting the following env vars:
AIRFLOW_CTX_DAG_OWNER=***
AIRFLOW_CTX_DAG_ID=gcs_to_bq_dag
AIRFLOW_CTX_TASK_ID=gcs_2_gcs_task
AIRFLOW_CTX_EXECUTION_DATE=2022-02-07T00:00:00+00:00
AIRFLOW_CTX_DAG_RUN_ID=scheduled__2022-02-07T00:00:00+00:00
[2022-02-08 17:37:05,240] {crypto.py:82} WARNING - empty cryptography key - values will not be stored encrypted.
[2022-02-08 17:37:05,241] {gcs_to_gcs.py:346} INFO - Delimiter ignored because wildcard is in prefix
[2022-02-08 17:37:05,243] {taskinstance.py:1700} ERROR - Task failed with exception
Traceback (most recent call last):
  File "/home/airflow/.local/lib/python3.7/site-packages/airflow/models/taskinstance.py", line 1329, in _run_raw_task
    self._execute_task_with_callbacks(context)
  File "/home/airflow/.local/lib/python3.7/site-packages/airflow/models/taskinstance.py", line 1455, in _execute_task_with_callbacks
    result = self._execute_task(context, self.task)
  File "/home/airflow/.local/lib/python3.7/site-packages/airflow/models/taskinstance.py", line 1511, in _execute_task
    result = execute_callable(context=context)
  File "/home/airflow/.local/lib/python3.7/site-packages/airflow/providers/google/cloud/transfers/gcs_to_gcs.py", line 274, in execute
    self._copy_source_with_wildcard(hook=hook, prefix=prefix)
  File "/home/airflow/.local/lib/python3.7/site-packages/airflow/providers/google/cloud/transfers/gcs_to_gcs.py", line 348, in _copy_source_with_wildcard
    objects = hook.list(self.source_bucket, prefix=prefix_, delimiter=delimiter)
  File "/home/airflow/.local/lib/python3.7/site-packages/airflow/providers/google/cloud/hooks/gcs.py", line 684, in list
    client = self.get_conn()
  File "/home/airflow/.local/lib/python3.7/site-packages/airflow/providers/google/cloud/hooks/gcs.py", line 152, in get_conn
    credentials=self._get_credentials(), client_info=self.client_info, project=self.project_id
  File "/home/airflow/.local/lib/python3.7/site-packages/airflow/providers/google/common/hooks/base_google.py", line 256, in _get_credentials
    credentials, _ = self._get_credentials_and_project_id()
  File "/home/airflow/.local/lib/python3.7/site-packages/airflow/providers/google/common/hooks/base_google.py", line 242, in _get_credentials_and_project_id
    delegates=delegates,
  File "/home/airflow/.local/lib/python3.7/site-packages/airflow/providers/google/cloud/utils/credentials_provider.py", line 335, in get_credentials_and_project_id
    return _CredentialProvider(*args, **kwargs).get_credentials_and_project()
  File "/home/airflow/.local/lib/python3.7/site-packages/airflow/providers/google/cloud/utils/credentials_provider.py", line 237, in get_credentials_and_project
    credentials, project_id = self._get_credentials_using_key_path()
  File "/home/airflow/.local/lib/python3.7/site-packages/airflow/providers/google/cloud/utils/credentials_provider.py", line 287, in _get_credentials_using_key_path
    self.key_path, scopes=self.scopes
  File "/home/airflow/.local/lib/python3.7/site-packages/google/oauth2/service_account.py", line 239, in from_service_account_file
    filename, require=["client_email", "token_uri"]
  File "/home/airflow/.local/lib/python3.7/site-packages/google/auth/_service_account_info.py", line 72, in from_filename
    with io.open(filename, "r", encoding="utf-8") as json_file:
FileNotFoundError: [Errno 2] No such file or directory: '/.google/credentials/google_credentials.json'
[2022-02-08 17:37:05,258] {taskinstance.py:1277} INFO - Marking task as UP_FOR_RETRY. dag_id=gcs_to_bq_dag, task_id=gcs_2_gcs_task, execution_date=20220207T000000, start_date=20220208T173705, end_date=20220208T173705
[2022-02-08 17:37:05,271] {standard_task_runner.py:92} ERROR - Failed to execute job 729 for task gcs_2_gcs_task
Traceback (most recent call last):
  File "/home/airflow/.local/lib/python3.7/site-packages/airflow/task/task_runner/standard_task_runner.py", line 85, in _start_by_fork
    args.func(args, dag=self.dag)
  File "/home/airflow/.local/lib/python3.7/site-packages/airflow/cli/cli_parser.py", line 48, in command
    return func(*args, **kwargs)
  File "/home/airflow/.local/lib/python3.7/site-packages/airflow/utils/cli.py", line 92, in wrapper
    return f(*args, **kwargs)
  File "/home/airflow/.local/lib/python3.7/site-packages/airflow/cli/commands/task_command.py", line 298, in task_run
    _run_task_by_selected_method(args, dag, ti)
  File "/home/airflow/.local/lib/python3.7/site-packages/airflow/cli/commands/task_command.py", line 107, in _run_task_by_selected_method
    _run_raw_task(args, ti)
  File "/home/airflow/.local/lib/python3.7/site-packages/airflow/cli/commands/task_command.py", line 184, in _run_raw_task
    error_file=args.error_file,
  File "/home/airflow/.local/lib/python3.7/site-packages/airflow/utils/session.py", line 70, in wrapper
    return func(*args, session=session, **kwargs)
  File "/home/airflow/.local/lib/python3.7/site-packages/airflow/models/taskinstance.py", line 1329, in _run_raw_task
    self._execute_task_with_callbacks(context)
  File "/home/airflow/.local/lib/python3.7/site-packages/airflow/models/taskinstance.py", line 1455, in _execute_task_with_callbacks
    result = self._execute_task(context, self.task)
  File "/home/airflow/.local/lib/python3.7/site-packages/airflow/models/taskinstance.py", line 1511, in _execute_task
    result = execute_callable(context=context)
  File "/home/airflow/.local/lib/python3.7/site-packages/airflow/providers/google/cloud/transfers/gcs_to_gcs.py", line 274, in execute
    self._copy_source_with_wildcard(hook=hook, prefix=prefix)
  File "/home/airflow/.local/lib/python3.7/site-packages/airflow/providers/google/cloud/transfers/gcs_to_gcs.py", line 348, in _copy_source_with_wildcard
    objects = hook.list(self.source_bucket, prefix=prefix_, delimiter=delimiter)
  File "/home/airflow/.local/lib/python3.7/site-packages/airflow/providers/google/cloud/hooks/gcs.py", line 684, in list
    client = self.get_conn()
  File "/home/airflow/.local/lib/python3.7/site-packages/airflow/providers/google/cloud/hooks/gcs.py", line 152, in get_conn
    credentials=self._get_credentials(), client_info=self.client_info, project=self.project_id
  File "/home/airflow/.local/lib/python3.7/site-packages/airflow/providers/google/common/hooks/base_google.py", line 256, in _get_credentials
    credentials, _ = self._get_credentials_and_project_id()
  File "/home/airflow/.local/lib/python3.7/site-packages/airflow/providers/google/common/hooks/base_google.py", line 242, in _get_credentials_and_project_id
    delegates=delegates,
  File "/home/airflow/.local/lib/python3.7/site-packages/airflow/providers/google/cloud/utils/credentials_provider.py", line 335, in get_credentials_and_project_id
    return _CredentialProvider(*args, **kwargs).get_credentials_and_project()
  File "/home/airflow/.local/lib/python3.7/site-packages/airflow/providers/google/cloud/utils/credentials_provider.py", line 237, in get_credentials_and_project
    credentials, project_id = self._get_credentials_using_key_path()
  File "/home/airflow/.local/lib/python3.7/site-packages/airflow/providers/google/cloud/utils/credentials_provider.py", line 287, in _get_credentials_using_key_path
    self.key_path, scopes=self.scopes
  File "/home/airflow/.local/lib/python3.7/site-packages/google/oauth2/service_account.py", line 239, in from_service_account_file
    filename, require=["client_email", "token_uri"]
  File "/home/airflow/.local/lib/python3.7/site-packages/google/auth/_service_account_info.py", line 72, in from_filename
    with io.open(filename, "r", encoding="utf-8") as json_file:
FileNotFoundError: [Errno 2] No such file or directory: '/.google/credentials/google_credentials.json'
[2022-02-08 17:37:05,289] {local_task_job.py:154} INFO - Task exited with return code 1
[2022-02-08 17:37:05,321] {local_task_job.py:264} INFO - 0 downstream tasks scheduled from follow-on schedule check
